Workbook

Sheet 【重要】始めにお読みください
B1: 外部発表_広告表示チェックシート | E1: Ver.1.1 (2025/11/13)
B18: 外部発表の種別※ | D18: 使用するチェックシート | E18: (A)(B)どちらをチェックしたか”〇”を付けて下さい
B19: (A) | C19: 報道発表、TVCM、ラジオCM、新聞広告、雑誌広告、Web/SNS広告、チラシ/パンフレット、OOH（ポスター/交通広告/看板） 、展示会出展用広告 | D19: 「広告・宣伝用」チェックシート 「共通」チェックシート
B20: (B) | C20: 論文、技術投稿、出版、学会講演、技術解説（注） （注）イベント・セミナー、WEB上での発表含 | D20: 「論文・書籍・技術解説用 _総括表」チェックシート 「論文・書籍・技術解説用_個別確認」チェックシート 「共通」チェックシート | E20: 〇
C22: ※媒体を問いません（紙、WEB、HP、DVD等）
C24: 問合せ先：外部発表_広告表示チェックシート事前照会 | D24: （Form形式）

Sheet (A)広告・宣伝用
A1: 外部発表_広告表示チェックシート（広告・宣伝用）
H2: 45962
H3: 広報部門、営業推進部門、知財・輸出部門
B6: 基本情報
C7: 施策名 | N7: NTT
C8: 施策主管会社 | N8: NTTグリーン＆フード
C9: 施策主管組織 | N9: NTTソノリティ
C10: 原稿作成者 発表者
C11: チェック実施者 | E11: ※原稿作成者・発表者以外がチェック実施すること | N11: NTT AI-CIX
C12: 広告種別 | J12: FALSE | K12: FALSE | N12: NTTイノベーティブデバイス | Q12: OOH（ポスター/交通広告/看板）
D13: TVCM、新聞広告については持株広報部門へ事前照会をお願いします | N13: NTTプレシジョンメディシン
C14: 広告内容 | J14: FALSE | N14: NTTテクノクロス
J15: FALSE
J16: FALSE
B19: 1. ブランド観点
C20: 項番 | E20: はい | F20: いいえ | G20: 対象外 | H20: 補足・備考
C21: (1) | D21: 最新の「NTT / NTTグループ ブランドガイドライン」※を参照し、CI/GI規定、ブランドカラー、フォント、各種ロゴ等について、ガイドラインに沿った広告表現になっている ※ブランドガイドライン： https://nnn.gvm-jp.groupis-gn.ntt/jp/GI/ | J21: FALSE | K21: FALSE | L21: FALSE
C22: (2) | D22: 広告表現や施策によって目指すところが、自社のビジョンと矛盾していない | J22: FALSE | K22: FALSE | L22: FALSE
C23: (3) | D23: 事業環境を取り巻く状況を踏まえて適切なタイミングでの公開となっている （ネガティブなトレンドはないか） | J23: FALSE | K23: FALSE | L23: FALSE
D24: また、使用する製品名について知財部門に事前照会済である | E24: FALSE | F24: FALSE | G24: FALSE
C25: (4) | D25: （新たな）タレントを起用していない※ | H25: 写真素材のモデルは対象外とする | J25: FALSE | K25: FALSE | L25: FALSE
D26: ※公開範囲問わず、タレント起用をご検討の際は事前に持株会社 広報部門へご相談ください | H26: 持株会社 広報部門へは営業推進部広報部門から連絡する （計画段階で広報部門へ相談）
C27: (5) | D27: お客さまにとって分かりにくい専門用語はない （専門用語を用いている場合でも、用語の内容を説明している） | J27: FALSE | K27: FALSE | L27: FALSE
C28: (6) | D28: 差別的な表現、お客さまが不快感を抱くような表現、持株会社やNTTグループの品位を低下させるような表現等がない | J28: FALSE
C29: (7) | D29: あいまいな表現や、誤解を生む可能性がある表現等がない
C30: (8) | D30: 他社（者）や業界、業種を批判・否定するような表現になっていない
C31: (9) | D31: 全体を通し、ネガティブな表現になっていない
C32: (10) | D32: 事実よりも誇張した表現が含まれていない | J32: FALSE
C33: (11) | D33: 事実と関係性の低いビジュアルを用いていない （事実と関連がないのに、「子どもの笑顔」「豊かな自然」等の写真やイメージの付与を行わない※） ※子どもを広告に起用する場合は、「サステナビリティ・コミュニケーションガイド2023」 （2023年株式会社電通作成）のP50を参照 https://www.group.dentsu.com/jp/sustainability/pdf/sustainability-communication-guide2023.pdf | J33: FALSE | K33: FALSE
C34: (12) | D34: 数値を表示する場合、その数値の根拠や算出方法が明確に示されている
C35: (13) | D35: 表示する名称・スペックは全て正確に記載している | J35: FALSE
C36: (14) | D36: 掲載する情報は最新のものである、もしくは、変動がある情報については、いつ時点の情報か明示している
C37: (15) | D37: クリエイティブについて不具合があった場合、その修理/修復/賠償等の責任の所在は明確になっており、また、契約書等で合意がなされている | H37: 契約書等を決裁文書に添付する事
C38: (16) | D38: 個人情報が含まれる場合、個人情報の利用、管理などに十分な配慮がなされている
C39: (17) | D39: 広告に含まれる実験データや事例について、サンプル化・匿名化がなされている
C40: 【TVCMの場合】
C41: 対象の場合は以下チェック後、広報部門へご連絡ください
C42: (18) | D42: 文字表示（特に注釈類を含むもの）の露出秒数が2秒以上となっている | L42: FALSE
C43: (19) | D43: 文字数が1行に30文字※以内で2行以内となっている ※記号はカウントする、スペースはカウントしない
C44: (20) | D44: 注釈が3行以上にわたる場合は、訴求ポイント等注釈以外の文字も含めて視聴者が通常の見方で読み切ることができる秒数（最低3秒以上）を個別具体的に計測する等して十分に確保されている
...

Sheet (B)論文・書籍・技術解説用 _総括表
A1: 外部発表_広告表示チェックシート(論文・書籍・技術解説用） : 統括表
A3: 本シートは書き込みセル以外を保護（ロック）しています。補足内容などの記載が必要な場合は、「補足・注記事項」欄を使用して下さい。
A5: １．発表案件（本チェックシートでのチェック対象）
B7: 本項は、原稿作成者、発表予定者等、チェックを受ける者が記載すること
B8: 項 目 | D8: 内 容
B9: 発表タイトル | D9: claude codeのログにタイムスタンプをいれよう
B10: 発表の種類(*1) | D10: Webサイトへの記事投稿
C11: 国名 | D11: 日本
B12: 発表先 | C12: 組織名(*2) | D12: クラスメソッド株式会社
C13: 掲載誌名等(*3) | D13: Zenn
B14: 発表予定時期(*4) | D14: 46181
B15: 原稿作成者・発表者 | C15: 所属 | D15: SED
C16: 氏名 | D16: 上原潤二
B17: 他社共同発表者 | C17: 企業名 | D17: なし
C18: 共同発表とする経緯
B19: 発表の趣旨・目的 | D19: 当社所属社員＋当社の技術力アピール
B21: (*1) 論文、雑誌への記事投稿、セミナー講演、展示会出展など
B22: (*2) 学会名、出版元、展示会主催者など
B23: (*3) 掲載誌名・?年?月号、学会の研究会名／大会名、展示会名
B24: (*4) 雑誌等の発行予定日、セミナー開催日、展示会開催期間(開始日、終了日）
A26: ２． チェック実施 | C26: 原稿作成者／発表者によるチェックは無効とします。
B28: 項 目 | D28: 内 容
B29: チェックした対象物(*1) | D29: 発表原稿
B30: チェック実施日 | D30: 46160
B31: チェック実施者(*2) (チェック責任者) | C31: チェック実施範囲 | D31: Ａ項－Ｈ項（含む、Ｇ項）
C32: 所属 | D32: SED
C33: 職位
C34: 氏名
B35: 補足事項など
B37: (*1) 記載例；「・・・論文の草稿」、「〇〇セミナーでの発表草稿」等
B38: (*2) 事業部長等重要な組織の長又は、事業部長等重要な組織の長から指示された者がチェックを実施すること
A40: ３． チェック結果
B42: 個々のチェック結果について、以下の確認をします。
B43: チェック結果 | D43: 対 応
B44: □ | C44: チェックがされていない項目です。■、◆、▼になるようチェックをして下さい。
B45: ◆ | C45: 添付資料の添付、又は、決裁文書への特記が必要とされるチェック結果です。指示事項に従って下さい。
B46: ■又は▼ | C46: 特に、リスク要因は無いと判断されます。
C48: 注 「チェック結果」欄は、「個別チェック」シートでの結果が自動反映されます。
A49: 項 目 | C49: チェック結果 （注） | D49: チェック事項概要 | E49: 指示事項
A50: Ａ 他社情報保護 | E50: -
...

Sheet (B)論文・書籍・技術解説用_個別確認
A1: 外部発表_広告標チェックシート(論文・書籍・技術解説用） ： 個別確認シート
B3: 確認方法 １)各項番の「チェック内容」について確認（Ｙｅｓ又はＮｏ）し、「サブチェック結果」欄の該当欄を、「●」を入力（メニュー選択）し、チェック内容欄に記載の「指示事項」に従って下さい。 ２）チェックに関して、補足などコメントがある場合は、右端のコメント欄に記載して下さい。 ３）「サブチェック結果」の選択により、「チェック結果」は自動的に設定されます。
A5: Ａ 他社情報保護（契約遵守）
B6: 他社から機密情報として受領した情報の扱いについて、契約/受領条件を満足していることを確認する
A8: チェック結果 | B8: 項番 | C8: サブチェック結果 | D8: チェック内容 | E8: 指示事項 | F8: コメント
A9: =IF(AND(C10="●",C11="●"),"error",IF(C10="●","■",IF(C11="●","◆","□"))) -> ■ | B9: Ａ１ | D9: 他社から機密情報として受領した営業情報／技術情報／ノウハウ情報が記載されているか？ Yes、Noいずれか該当する項の○を●にする。 | E9: =IF(AND(C10="●",C11="●"),"error【Yes/Noどちらかを●にしてください】",IF(C11="●","「他社からの承諾書」をチェックシートに添付してください。",IF(NOT(C10="●"),"A１項未チェックです。","-"))) -> -
B10: No | C10: ● | D10: 記載が無い。 ＝＞ Ａ２項のチェックに進む。
B11: Yes | C11: ○ | D11: 記載しているが、当該他社からの承諾文書を得ている（口頭での許諾では不足です。）。 ＝＞ Ａ２項のチェックに進む。
A12: =IF(AND(C13="●",C14="●"),"error",IF(C13="●","■",IF(C14="●","◆","□"))) -> ■ | B12: Ａ２ | D12: 当社が受注開発したシステムの機能・構成等を事例として記載するか？ Yes、Noいずれか該当する項の○を●にする。 | E12: =IF(AND(C13="●",C14="●"),"error【Yes/Noどちらかを●にしてください】",IF(C14="●","発注元からの承諾書をチェックシートに添付してください。",IF(NOT(C13="●"),"A2項未チェックです。","-"))) -> -
B13: No | C13: ● | D13: 記載していない（発注元との関係を特定できない内容、形態にしている場合も含む）。 ＝＞ Ｂ項のチェックに進む。
B14: Yes | C14: ○ | D14: 記載しているが、発注元から、内容、媒体、時期について文書による承諾を得ている（口頭での許諾では不足です。）。 ＝＞ Ｂ項のチェックに進む。
A16: Ｂ 自社情報保護
B17: 当社の機密情報(営業情報、技術情報、ノウハウ情報）が保護、権利確保できていること
A18: チェック結果 | B18: 項番 | C18: サブチェック結果 | D18: チェック内容 | E18: 指示事項 | F18: コメント
A19: =IF(AND(C20="●",C21="●"),"error",IF(C20="●","■",IF(C21="●","◆","□"))) -> ■ | B19: Ｂ１ | C19: 営業情報保護 | D19: 当社の未公開の営業情報を記載しているか？ No,Yes（承諾有）,Yes（承諾無し）いずれか該当する項の○を●にする。 | E19: =IF(AND(C20="●",C21="●"),"error【Yes/Noどちらかを●にしてください】",IF(C21="●","公開する理由/関連組織からの承諾を決裁文書に記載してください。",IF(NOT(C20="●"),"Ｂ１項未チェックです。","-"))) -> -
B20: No | C20: ● | D20: 未公開の営業情報を記載していない。 ＝＞ Ｂ２項のチェックに進む。
B21: Yes | C21: ○ | D21: 未公開の営業情報を記載しているが、公開する理由（報道発表、プロモーション等）があり、社内関連組織（当該営業情報の保有部門）から承諾を得ている。 ＝＞ Ｂ２項のチェックに進む。
A22: =IF(AND(C23="●",C24="●"),"error",IF(C23="●","■",IF(C24="●","◆","□"))) -> ◆ | B22: Ｂ２ | C22: ノウハウ保護 | D22: 技術情報、ノウハウ情報を公表する場合、当社権利として確保するために特許出願がされている、又は特許出願の手続きが進められているか？ Yes,Noいずれか該当する項の○を●にする。 | E22: =IF(AND(C23="●",C24="●"),"error【Yes/Noどちらかを●にしてください】",IF(C24="●","技術内容の公表ではない／公知情報である等、特許出願予定の無いことを決裁文書に記載してください。",IF(NOT(C23="●"),"Ｂ２項未チェックです。","-"))) -> 技術内容の公表ではない／公知情報である等、特許出願予定の無いことを決裁文書に記載してください。
B23: Yes | C23: ○ | D23: 発表予定内容について、特許出願済み／出願手続き／知財担当に相談している。 ＝＞ Ｃ項のチェックに進む。
B24: No | C24: ● | D24: 技術内容についての公表ではない、又は、公知の情報を寄せ集め(例えば、技術解説記事)なので、特許出願の予定無し。 ＝＞ Ｃ項のチェックに進む。
A26: Ｃ 公表後の権利帰属について
A28: チェック結果 | B28: 項番 | C28: サブチェック結果 | D28: チェック内容 | E28: 指示事項 | F28: コメント
A29: =IF(AND(C30="●",C31="●"),"error",IF(C30="●","■",IF(C31="●","◆","□"))) -> ■ | B29: Ｃ１ | C29: 著作権保護 | D29: 著作権は当社に留保される条件となっているか？ Yes、Noいずれか該当する項の○を●にする。 | E29: =IF(AND(C30="●",C31="●"),"error【Yes/Noどちらかを●にしてください】",IF(C31="●","著作権譲渡しても自社での使用/改変はできるなどの業務に支障の無い旨決裁文書に記載してください。",IF(NOT(C30="●"),"Ｃ１項未チェックです。","-"))) -> -
B30: Yes 著作権留保 | C30: ● | D30: 当社の著作物として公表する。 ⇒ Ｄ項のチェックに進む。
B31: No 著作権譲渡 | C31: ○ | D31: 著作権を主催者等に譲渡する条件とされているが、譲渡しても業務に支障はない。 （公表後、当社で他目的に複写、改変等が自由にできるなど） ⇒ Ｄ項のチェックに進む。
A33: Ｄ 他社権利の侵害防止
B34: 他人の著作物の一部を利用している場合のチェック事項
A35: チェック結果 | B35: 項番 | C35: サブチェック結果 | D35: チェック内容 | E35: 指示事項 | F35: コメント
A36: =IF(AND(C37="●",OR(C38="●",C39="●")),"error",IF(AND(C38="●",C39="●"),"error",IF(C37="●","■",IF(C38="●","▼",IF(C39="●","▼","□"))))) -> ▼ | B36: Ｄ１ | C36: 他社著作物 | D36: 他社(者)の著作物の全部又は一部を、そのまま或いは修正などして使用しているか？ 次の①、②、③の該当する項の○を●にする。 | E36: =IF(AND(C37="●",OR(C38="●",C39="●")),"error【①②③の何れかを●にしてください】",IF(AND(C38="●",C39="●"),"error【②③の何れかを●にしてください】",IF(C37="●","-",IF(C38="●","-",IF(C39="●","-","Ｄ１項未チェックです。"))))) -> -
B37: ① （不使用） | C37: ○ | D37: 他社(者)著作物を使用していない。 ＝＞ Ｅ項のチェックに進む。
B38: ② (改変無し使用) | C38: ● | D38: 他社(者)著作物を改変・修正せずに使用している。 ＝＞ Ｄ２項をチェックする。
B39: ③ (改変有り使用) | C39: ○ | D39: 他社(者)著作物を改変・修正して使用している。 ＝＞ Ｄ３項をチェックする。
A40: =IF(A36="■","▼",IF(AND(A36="▼",C39="●"),"▼",IF(AND(C41="●",C42="●"),"◆",IF(C41="●","◆",IF(C42="●","◆","□"))))) -> ◆ | B40: Ｄ２ | C40: 引用 | D40: 他社(者)著作物の全部／一部の表現を変更せずに利用している場合、適正に利用しているか？ 次の①、②の該当する項の○を●にする（複数の他者著作物が有る場合は①②共に●も可） | E40: =IF(A36="■","Ｄ２項チェック不要です。",IF(AND(A36="▼",C39="●"),"Ｄ２項チェック不要です。",IF(AND(C41="●",C42="●"),"「他社（者）著作物の使用許諾文書」および「引用チェックシート」を添付して下さい。使用許諾の許諾期間がある場合は公表する期間が許諾期間に含まれる事の証跡を示してください。",IF(C41="●","他社（者）著作物の使用許諾文書を添付して下さい。使用許諾の許諾期間がある場合は公表する期間が許諾期間に含まれる事の証跡を示してください。",IF(C42="●","引用チェックシートを添付して下さい。","Ｄ２項未チェックです。"))))) -> 引用チェックシートを添付して下さい。
B41: ① （許諾取得） | C41: ○ | D41: 利用した著作物の著作権者が承諾していることを示す文書がある【著作権帰属先（Ｃ１項結果）の説明もすること】。 ＝＞ Ｅ項のチェックに進む
B42: ② （引用） | C42: ● | D42: 著作権者から承諾を得ていないが、著作権法の「引用」の条件を満たしていることを、「引用チェックシート」にて確認できている。 ＝＞ Ｅ項のチェックに進む
D43: ここをクリックすると、『引用チェックシート』を取得できます。
A44: =IF(A36="■","▼",IF(AND(A36="▼",C38="●"),"▼",IF(AND(C45="●",C46="●"),"◆",IF(C45="●","◆",IF(C46="●","◆","□"))))) -> ▼ | B44: Ｄ３ | C44: 改変利用 | D44: 他社(者)著作物の全部／一部を変更・修正・改変・翻案して利用している場合、適正な利用か？ 次の①、②の該当する項の○を●にする。 | E44: =IF(A36="■","Ｄ３項チェック不要です。",IF(AND(A36="▼",C38="●"),"Ｄ３項チェック不要です。",IF(AND(C45="●",C46="●"),"「他社（者）著作物の使用許諾文書」および、知的財産担当と相談した結果、妥当な修正である旨が確認された文書を添付して下さい。",IF(C45="●","他社（者）著作物の使用許諾文書を添付して下さい。使用許諾の許諾期間がある場合は公表する期間が許諾期間に含まれる事の証跡を示してください。",IF(C46="●","知的財産担当と相談した結果、妥当な修正である旨が確認された文書を添付して下さい。","Ｄ３項未チェックです。"))))) -> Ｄ３項チェック不要です。
B45: ① （許諾取得） | C45: ○ | D45: 変更・修正・改変・翻案について、利用した著作物の著作権者が承諾していることを示す文書がある【著作権帰属先（Ｃ１項結果）の説明もすること】。 ＝＞ Ｅ項のチェックに進む
B46: ② （正当性） | C46: ○ | D46: 著作権者から承諾を得ていないが、知的財産担当により妥当な修正等である旨が確認されたことの文書がある。 ＝＞ Ｅ項のチェックに進む
A48: Ｅ 公表の形態
...

Sheet (A)(B)共通
A1: 外部発表_広告表示チェックシート（(A)(B)共通）
H2: 45962
H3: 広報部門、営業推進部門、知財・輸出部門
B6: 4. 人権関連
C7: 項番 | D7: 内容 | E7: はい | F7: いいえ | G7: 対象外 | H7: 補足・備考
C8: (1) | D8: 性別による役割の固定を行っていない | J8: FALSE | K8: FALSE
C9: (2) | D9: アンコンシャス・バイアスに注意し、ステレオタイプな描写を行っていない （彼、彼女など性別を特定できる表現ではなく、ご本人のお名前や、性別を特定しない呼び方に変更している）
C10: (3) | D10: 不自然な表現、不快な表現となっておらず、人体が見切れているように見えるイラストは利用していない （見切れている場合は壁や机など境界とセットで描いている）
C11: (4) | D11: 擬人化した動物の画を使用する場合、差別に通じる不快な表現となっていない
C12: (5) | D12: 思想・宗教・民族等のシンボルあるいはそれを模した図案などを使用していない
C13: (6) | D13: セクシャルハラスメントをはじめ、各種ハラスメントを想起させるイラスト・コンテンツとなるおそれはない
C14: (7) | D14: 海外において否定的なハンドサインを使っていない（サムズアップ、ピースサイン、OKサイン、特定の指を立てる、等）
C15: (8) | D15: 次の差別につながるおそれのある言葉の使用や表現はない ・部落差別 ・障がい者差別 ・性の差別（性的指向の差別・性自認の差別含む）・人種民族差別 ・職業差別 ・身体差別 ・エイズ差別 ・学歴差別 ・思想、信条に対する差別 ・地域差別 ・年齢差別 ・階級差別 ・外国人に対する差別
B17: 5. サステナビリティ関連
C18: 項番 | D18: 内容 | E18: はい | F18: いいえ | G18: 対象外 | H18: 補足・備考
C19: (1) | D19: 不都合な事実を伝えず、良い情報のみを伝達している内容になっていない （製品や企業活動の一部にのみ該当する環境訴求をもって、製品や企業活動全体に関する環境訴求を行っていない、 また、カーボン・オフセットのみに基づき、環境への悪影響が軽減されたなどと訴求していない）
C20: (2) | D20: 環境に関する訴求では、内容が国際社会での合意、科学的見解と矛盾していない （国連気候変動枠組条約締約国会議(COP)で採択される条約や、気候変動に関する政府間パネル(IPCC)の「1.5℃特別報告書」等の内容と矛盾していない）
C21: (3) | D21: 国や地域、時代や社会の状況を考慮した内容となっている （個人のリテラシーや国や社会の状況によって、具体的にどのような表現がウォッシュに相当するのかの判断基準は大きく異なるが、宗教や習慣、信条等に配慮した内容になっている）
C22: (4) | D22: 最新の「環境表示ガイドライン」※に沿って、下記の 5 つの基本項目に沿っている ① あいまいな表現や環境主張は行わないこと ② 環境主張の内容に説明文を付けること ③ 環境主張の検証に必要なデータ及び評価方法が提供可能であること ④ 製品又は工程における比較主張は LCA 評価、数値等により適切になされていること ⑤ 評価及び検証のための情報にアクセスが可能であること ※環境省「環境表示ガイドライン」 https://www.env.go.jp/policy/hozen/green/ecolabel/guideline/guideline.pdf
C23: (5) | D23: 【SDGsロゴを使用する場合】 国連のガイドライン※を守っている ※下記参照 ・ ポスター・ロゴ・アイコンおよびガイドライン（日本語：国際連合広報センター）： https://www.unic.or.jp/files/SDG_Guidelines_AUG_2019_Final_ja.pdf ・よく寄せられる質問（日本語：国際連合広報センター）： https://www.unic.or.jp/files/SDG_Branding_FAQ_Japanese.pdf

Sheet 改版履歴
B2: 年月日 | C2: 版数 | D2: 改版内容
B3: 2024/12/ | C3: 1 | D3: 持株広告審査制度に従ったチェック項目の見直し
B4: 2025/11/ | C4: 1.1 | D4: ・持株広告審査制度改正に従ったチェック項目の見直し ・知財財産権に対する確認項目の追加 ・補足事項の追記
